Workbook

Sheet bs
A1: M/S XYZ CO.
A2: Balance Sheet as at 31 March, 2025
E3: (Amount in Rs.) | F3: (Amount in Rs.)
B4: Particulars | D4: Note No. | E4: As at 31.03.2025 | F4: As at 31.03.2024
A5: I | B5: OWNERS’ FUNDS AND LIABILITIES
A6: 1 | B6: Owners’ Fund
A7: (a) | B7: Owners Capital Account | D7: 2 | E7: =capital!G10 -> 0 | F7: =capital!G11 -> 0
E8: =SUM(E7:E7) -> 0 | F8: =SUM(F7:F7) -> 0
A10: 2 | B10: Non-current liabilities
A11: (a) | B11: Long-term borrowings | D11: 3 | E11: ='notes to bs'!D19 -> 0 | F11: ='notes to bs'!E19 -> 0
A13: 3 | B13: Current liabilities
A14: (a) | B14: Short-term borrowings | D14: 3 | E14: ='notes to bs'!D34 -> 0 | F14: ='notes to bs'!E34 -> 0
A15: (b) | B15: Trade Payables | D15: 4
B16: (i) total outstanding dues of micro, small and medium enterprises and; | E16: ='notes to bs'!D38 -> 0 | F16: ='notes to bs'!E38 -> 0
B17: (ii) total outstanding dues of creditors other than Micro, Small and Medium Enterprises | E17: ='notes to bs'!D39 -> 0 | F17: ='notes to bs'!E39 -> 0
A18: (c) | B18: Other current liabilities | D18: 5 | E18: ='notes to bs'!D65 -> 0 | F18: ='notes to bs'!E65 -> 0
A19: (d) | B19: Short-Term Provisions | D19: 6 | E19: ='notes to bs'!D71 -> 0 | F19: ='notes to bs'!E71 -> 0
E20: =SUM(E11:E19) -> 0 | F20: =SUM(F11:F19) -> 0
B21: Total | E21: =E8+E20 -> 0 | F21: =F8+F20 -> 0
A23: II | B23: ASSETS
A24: 1 | B24: Non-current assets
A25: (a) | B25: Property, Plant and Equipment and Intangible assets
B26: (i) Property, Plant and Equipment | D26: 7 | E26: ='Fixed Assets C. Yr.'!I68 -> 0 | F26: ='Fixed Assets P. Yr.'!I37 -> 0
B27: (ii) Non-Current Investments | D27: 8 | E27: ='notes to bs'!D81 -> 0 | F27: ='notes to bs'!E81 -> 0
E28: =SUM(E26:E27) -> 0 | F28: =SUM(F26:F27) -> 0
A29: 2 | B29: Current assets
A30: (a) | B30: Current Investments | E30: 0 | F30: 0
A31: (a) | B31: Inventories | D31: 15 | E31: ='notes to p&l'!D27 -> 0 | F31: ='notes to p&l'!E27 -> 0
A32: (b) | B32: Trade Receivables | D32: 9 | E32: ='notes to bs'!D101 -> 0 | F32: ='notes to bs'!E101 -> 0
A33: (c) | B33: Cash and bank balances | D33: 10 | E33: ='notes to bs'!D120 -> 0 | F33: ='notes to bs'!E120 -> 0
A34: (d) | B34: Short Term Loans and Advances | D34: 11 | E34: ='notes to bs'!D150 -> 0 | F34: ='notes to bs'!E150 -> 0
A35: (e) | B35: Other Current Assets | D35: 12 | E35: ='notes to bs'!D160 -> 0 | F35: ='notes to bs'!E160 -> 0
E36: =SUM(E31:E35) -> 0 | F36: =SUM(F31:F35) -> 0
B37: Total | E37: =E28+E36 -> 0 | F37: =F28+F36 -> 0
B39: Summary of significant accounting policies | D39: 1
B41: The accompanying notes are an integral part of the financial statements

Sheet p&l
A1: =bs!A1 -> M/S XYZ CO.
A2: Statement of Profit & Loss for the year ended 31 March, 2025
F3: (Amount in Rs.)
B4: Particulars | D4: =bs!D4 -> Note No. | E4: Year ending 31.03.2025 | F4: Year ending 31.03.2024
A5: I | B5: Revenue from operations | D5: 13 | E5: ='notes to p&l'!D8 -> 0 | F5: ='notes to p&l'!E8 -> 0
A6: II | B6: Other Income | D6: 14 | E6: ='notes to p&l'!D13 -> 0 | F6: ='notes to p&l'!E13 -> 0
A7: III | B7: Total Income (I+II) | E7: =SUM(E5:E6) -> 0 | F7: =SUM(F5:F6) -> 0
A9: IV | B9: Expenses:
A10: (a) | B10: Cost of material consumed | D10: 15 | E10: ='notes to p&l'!D29 -> 0 | F10: ='notes to p&l'!E29 -> 0
A11: (b) | B11: Employee benefits expense | D11: 16 | E11: ='notes to p&l'!D40 -> 0 | F11: ='notes to p&l'!E40 -> 0
A12: (c) | B12: Finance cost | D12: 17 | E12: ='notes to p&l'!D47 -> 0 | F12: ='notes to p&l'!E47 -> 0
A13: (d) | B13: Depreciation and amortization expense | D13: 18 | E13: ='notes to p&l'!D56 -> 0 | F13: ='notes to p&l'!E56 -> 0
A14: (e) | B14: Other expenses | D14: 19 | E14: ='notes to p&l'!D87 -> 0 | F14: ='notes to p&l'!E87 -> 0
B15: Total expenses | E15: =SUM(E10:E14) -> 0 | F15: =SUM(F10:F14) -> 0
A17: V | B17: Profit before tax (III-VI) | E17: =E7-E15 -> 0 | F17: =F7-F15 -> 0
A19: VI | B19: Tax expense:
A20: (a) | B20: Current tax | E20: 0 | F20: 0
A21: (b) | B21: Excess/ Short provision of tax relating to earlier years
E22: =SUM(E20:E21) -> 0 | F22: =SUM(F20:F21) -> 0
A24: VII | B24: Profit/(Loss) for the year (XI+XIV) | E24: =E17-E22 -> 0 | F24: =F17-F22 -> 0
B26: The accompanying notes are an integral part of the financial statements

Sheet notes to accounts
A1: =bs!A1 -> M/S XYZ CO.
A2: Notes on Financial Statement for the year end 31 March, 2025
A4: 1.1 | B4: Business Information
B5: M/s XYZ….. is proprietership Consern in which …... is Proprietor. The firm is engaged in the business of Trading.
A7: 1.2 | B7: Significant Accounting Policies
B8: The Accounts are prepared in accordance with the accounting principles generally accepted in India
B9: and are in line with the relevant laws.
A11: A | B11: General
B12: Accounting Policies not specifically referred to otherwise are consistent and in consonance with
B13: generally accepted accounting policies
A15: B | B15: Property Plant & Equipments
B16: Fixed Assetsare stated at written down value as on date.
B17: Depreciation on Fixed Assets has been provided on WDV in accordance with the rates prescribed under
B18: Income Tax Act, 1961.
A20: C | B20: Revenue Recognition
B21: Revenue is recognized on accrual basis.
A23: D | B23: Inventories
B24: Inventories are valued at cost or net realizable price whichever is lower, except scrap at net realisable value. The cost formula used for valuation of inventories are:-
B25: 1. In respect of raw material and packing material, have been valued at cost on FIFO basis.
B26: 2. Finished goods are valued on retail price method.
A28: E | B28: Borrowing Costs
B29: Borrowing costs that are directly attributable to acquisition or construction of qualifying assets are
B30: treated as part of cost of capital assets. Other borrowing costs are treated as expenses for the period
B31: in which they are incurred.
A33: 1.3 | B33: Contingent liability :Nil
A35: 1.4 | B35: In the opinion of the proprietor, all the current assets, loans and advances have a value on
B36: realization in the ordinary course of business at least equal to the amount at which they are stated.
A38: 1.5 | B38: Debit or credit balances, in whatever account, are subject to confirmation from parties and
B39: as such their effect on Profit & Loss Account cannot be reflected.
A41: 1.6 | B41: The micro, Small and Medium Enterprise Development Act, 2006 has come into force with effect
B42: from October 2, 2006. As per the act, the asssessee is required to identify the Micro and Small
B43: Vendors/Service Providers and pay interest to them on overdue amount beyond the specified period
B44: irrespective of the terms agreed upon. The assessee has not paid any interest to such persons.
A46: 1.7 | B46: Notes on financial statements form an integral part of the Balance Sheet & Profit and Loss account
B47: and have been duly authenticated hereto.
B52: =bs!#REF! -> #REF! | G52: =bs!#REF! -> #REF!
B53: =capital!#REF! -> #REF! | G53: ='p&l'!#REF! -> #REF!

Sheet capital
A1: =bs!A1 -> M/S XYZ CO.
A2: Notes forming part of the Financial Statements for the year ended, 31st March, 2025
A4: Note - 2: Owner's Capital Account
A6: Curret Year (CY) | G6: (Amount in Rs.)
A7: Sr. No. | B7: Name of Proprietor | C7: As at 1st April 2024 | D7: Capital Introduced during the year | E7: Withdrawals during the year | F7: Share of Profit / Loss for the year | G7: As at 31st March 2025
A8: 1 | B8: XYZ | C8: =G11 -> 0 | F8: ='p&l'!E24 -> 0 | G8: =C8+D8-E8+F8 -> 0
C10: =SUM(C8:C9) -> 0 | D10: =SUM(D8:D9) -> 0 | E10: =SUM(E8:E9) -> 0 | F10: =SUM(F8:F9) -> 0 | G10: =C10+D10-E10+F10 -> 0
A11: Previous Year (PY) | F11: ='p&l'!F17 -> 0 | G11: =C11+D11-E11+F11 -> 0
B18: (Pushkal Soni) | F18: (DIMPAL JAIN)
B19: Chartered Accountant | F19: Proprietor
A24: =bs!A1 -> M/S XYZ CO.
A25: Notes forming part of the Financial Statements for the year ended, 31st March, 2023
A27: Note - 2: Owner's Capital Account
A29: Curret Year (CY) | G29: (Amount in Rs.)
A30: Sr. No. | B30: Name of Proprietor | C30: As at 1st April 2022 | D30: Capital Introduced during the year | E30: Withdrawals during the year | F30: Share of Profit / Loss for the year | G30: As at 31st March 2023
A31: 1 | B31: Dimpal Jain | C31: =G34 -> 7208848.3 | D31: =22111.6-13095 -> 9016.6 | E31: 2806454.8 | F31: ='p&l'!F24 -> 0 | G31: =C31+D31-E31+F31 -> 4411410.1
C33: =SUM(C31:C32) -> 7208848.3 | D33: =SUM(D31:D32) -> 9016.6 | E33: =SUM(E31:E32) -> 2806454.8 | F33: =SUM(F31:F32) -> 0 | G33: =C33+D33-E33+F33 -> 4411410.1
A34: Previous Year (PY) | C34: 5646494.5 | D34: 2298736 | E34: 1489928.3 | F34: 753546.06 | G34: =C34+D34-E34+F34 -> 7208848.3

Sheet notes to bs
A1: =bs!A1 -> M/S XYZ CO.
A2: =capital!A2 -> Notes forming part of the Financial Statements for the year ended, 31st March, 2025
E3: (Amount in Rs.)
A4: =bs!D11 -> 3 | B4: Long Term Borrowings | D4: As at 31.03.2025 | E4: As at 31.03.2024
B5: Secured
B6: Term loans
B7: from banks
B8: from other parties
B10: Total (A) | D10: =SUM(D7:D8) -> 0 | E10: =SUM(E7:E8) -> 0
B12: Unsecured
B13: Term loans
B14: from banks
B15: from related parties | D15: =Details!D13 -> 0 | E15: =Details!E13 -> 0
B16: from other parties
B18: Total (B) | D18: =SUM(D14:D17) -> 0 | E18: =SUM(E14:E17) -> 0
B19: Total (A) + (B) | D19: =+D18+D10 -> 0 | E19: =+E18+E10 -> 0
A22: =bs!D14 -> 3 | B22: Short Term Borrowings | D22: =D4 -> As at 31.03.2025 | E22: =E4 -> As at 31.03.2024
B23: Secured
B24: Loans repayable on demand
B25: Bank CC A/c | E25: 0
B26: (Secured by Hypothecation of charge on current assets of the company both present and Future)
B29: Total (A) | D29: =SUM(D25:D26) -> 0 | E29: =SUM(E25:E26) -> 0
B30: Unsecured
B31: Loans repayable on demand
B32: From related parties
B33: Total (B) | D33: =SUM(D32:D32) -> 0 | E33: =SUM(E32:E32) -> 0
B34: Total (A) + (B) | D34: =+D33+D29 -> 0 | E34: =+E33+E29 -> 0
E36: (Amount in Rs.)
A37: =bs!D15 -> 4 | B37: Trade payables | D37: =D22 -> As at 31.03.2025 | E37: =E22 -> As at 31.03.2024
B38: (a) Total outstanding dues of micro, small and medium enterprises | D38: =Details!D68 -> 0 | E38: =Details!E68 -> 0
B39: (b) Total outstanding dues of creditors other than micro, small and medium enterprises | D39: =Details!D62 -> 0 | E39: =Details!E62 -> 0
B40: Total Trade payables | D40: =SUM(D38:D39) -> 0 | E40: =SUM(E38:E39) -> 0
B41: Disclosure relating to suppliers registered under MSMED Act based on the information available with the entity Company: Nil
B42: Particulars | D42: =D37 -> As at 31.03.2025 | E42: =E37 -> As at 31.03.2024
B43: (a) Amount remaining unpaid to any supplier at the end of each accounting year:
B44: Principal | D44: =D40 -> 0 | E44: =E40 -> 0
B45: Interest
B46: Total
B47: (b) The amount of interest paid by the buyer in terms of section 16 of the MSMED Act, along with the amount of the payment made to the supplier beyond the appointed day during each accounting year.
B48: (c) The amount of interest due and payable for the period of delay in making payment (which have been paid but beyond the appointed day during the year) but without adding the interest specified under the MSMED Act.
...

Sheet notes to p&l
A1: =bs!A1 -> M/S XYZ CO.
A2: =capital!A2 -> Notes forming part of the Financial Statements for the year ended, 31st March, 2025
D4: (Amount in Rs.)
A5: ='p&l'!D5 -> 13 | B5: Revenue from operations | D5: ='p&l'!E4 -> Year ending 31.03.2025 | E5: ='p&l'!F4 -> Year ending 31.03.2024
B6: Sale of Goods
B8: Total revenue from operation | D8: =D6 -> 0 | E8: =E6 -> 0
D10: (Amount in Rs.)
A11: ='p&l'!D6 -> 14 | B11: Other Incomes | D11: =D5 -> Year ending 31.03.2025 | E11: =E5 -> Year ending 31.03.2024
B12: Rebate & Discount
B13: Total other incomes | D13: =SUM(D12:D12) -> 0 | E13: =SUM(E12:E12) -> 0
D15: (Amount in Rs.)
A16: ='p&l'!D10 -> 15 | B16: Cost of material consumed | D16: =D5 -> Year ending 31.03.2025 | E16: =E5 -> Year ending 31.03.2024
A18: (a) | B18: Inventories at the beginning of the year | D18: =E27 -> 0
A20: (b) | B20: Purchases
B21: -Purchase GST
A23: (c) | B23: Direct Expenses
A27: (d) | B27: Inventories at the end of the year | D27: ='GROSS PROFIT'!E13 -> 0
B29: Total (a+b+c-d) | D29: =SUM(D18:D25)-D27 -> 0 | E29: =SUM(E18:E24)-E27 -> 0
D32: (Amount in Rs.)
A33: ='p&l'!D11 -> 16 | B33: Employee benefits expense | D33: =D16 -> Year ending 31.03.2025 | E33: =E16 -> Year ending 31.03.2024
A34: (a) | B34: Salaries
A35: (b) | B35: Bonus
A36: (c) | B36: Staff & Labour welfare expenses
B40: Total Employee benefits expense | D40: =SUM(D34:D36) -> 0 | E40: =SUM(E34:E36) -> 0
D42: (Amount in Rs.)
A43: ='p&l'!D12 -> 17 | B43: Finance cost | D43: =D33 -> Year ending 31.03.2025 | E43: =E33 -> Year ending 31.03.2024
A44: (a) | B44: Bank Interest
A45: (b) | B45: Interest on Unsecured Loan
B47: Total Finance cost | D47: =SUM(D45:D46) -> 0 | E47: =SUM(E44:E45) -> 0
A52: =A1 -> M/S XYZ CO.
A53: =A2 -> Notes forming part of the Financial Statements for the year ended, 31st March, 2025
D54: (Amount in Rs.)
A55: ='p&l'!D13 -> 18 | B55: Depreciation and amortization expense | D55: =D33 -> Year ending 31.03.2025 | E55: =E33 -> Year ending 31.03.2024
B56: On tangible assets (Refer note 7) | D56: ='Fixed Assets C. Yr.'!H68 -> 0 | E56: ='Fixed Assets P. Yr.'!H37 -> 0
B57: Total Depreciation and amortization expense expense | D57: =SUM(D56:D56) -> 0 | E57: =SUM(E56:E56) -> 0
D59: (Amount in Rs.)
A60: ='p&l'!D14 -> 19 | B60: Other Expenses | D60: =D55 -> Year ending 31.03.2025 | E60: =E55 -> Year ending 31.03.2024
B61: Audit Fee
B62: Bank Charges
B63: Car Exp
...

Sheet PPE
A1: =bs!A1 -> M/S XYZ CO.
A2: ='notes to p&l'!A2 -> Notes forming part of the Financial Statements for the year ended, 31st March, 2025
A4: 7 Property, Plant and Equipment and Intangible Assets
B6: CURRENT YEAR (CY)
B7: Particulars /Assets | C7: Tangibles
C8: Building | D8: Furniture & Fixtures | E8: Plant And Machinery | F8: Computers | G8: Vehicles | H8: Total
B9: WDV as at 1 April 2024 | C9: =C39 -> 0 | D9: =D39 -> 0 | E9: =E39 -> 0 | F9: =F39 -> 0 | G9: =G39 -> 0 | H9: =H39 -> 0
B10: Additions | C10: ='Fixed Assets C. Yr.'!C60+'Fixed Assets C. Yr.'!D60 -> 0 | D10: =SUM('Fixed Assets C. Yr.'!C36:D36) -> 0 | E10: =SUM('Fixed Assets C. Yr.'!C11:D21) -> 0 | F10: ='Fixed Assets C. Yr.'!#REF!+'Fixed Assets C. Yr.'!#REF! -> #REF! | G10: =SUM('Fixed Assets C. Yr.'!C24:D33) -> 0 | H10: =SUM(C10:G10) -> #REF!
B11: Deductions/Adjustments | C11: 0 | D11: 0 | E11: =SUM('Fixed Assets C. Yr.'!#REF!) -> #REF! | F11: 0 | G11: =SUM('Fixed Assets C. Yr.'!E24:E33) -> 0 | H11: =SUM(C11:G11) -> #REF!
B12: Toal | C12: =+C9+C10-C11 -> 0 | D12: =+D9+D10-D11 -> 0 | E12: =+E9+E10-E11 -> #REF! | F12: =+F9+F10-F11 -> #REF! | G12: =G9+G10-G11 -> 0 | H12: =+H9+H10-H11 -> #REF!
B14: Depreciation/Adjustments
B15: At 1 April 2024 | C15: 0 | D15: 0 | E15: 0 | F15: 0 | G15: 0 | H15: =SUM(C15:G15) -> 0
B16: Additions | C16: ='Fixed Assets C. Yr.'!H60 -> 0 | D16: ='Fixed Assets C. Yr.'!#REF!+'Fixed Assets C. Yr.'!H36 -> #REF! | E16: =SUM('Fixed Assets C. Yr.'!H11:H21) -> 0 | F16: ='Fixed Assets C. Yr.'!#REF! -> #REF! | G16: =SUM('Fixed Assets C. Yr.'!H24:H33) -> 0 | H16: =SUM(C16:G16) -> #REF!
B17: Deductions/Adjustments | C17: 0 | D17: 0 | E17: 0 | F17: 0 | G17: 0 | H17: =SUM(C17:G17) -> 0
B18: Toal | C18: =+C15+C16-C17 -> 0 | D18: =+D15+D16-D17 -> #REF! | E18: =+E15+E16-E17 -> 0 | F18: =+F15+F16-F17 -> #REF! | G18: =G15+G16-G17 -> 0 | H18: =+H15+H16-H17 -> #REF!
B20: WDV as at 31 March 2025 | C20: =C12-C18 -> 0 | D20: =D12-D18 -> #REF! | E20: =E12-E18 -> #REF! | F20: =F12-F18 -> #REF! | G20: =G12-G18 -> 0 | H20: =H12-H18 -> #REF!
B25: PREVIOUS YEAR (PY)
B26: Particulars /Assets | C26: Tangibles
C27: Building | D27: Furniture & Fixtures | E27: Plant And Machinery | F27: Computers | G27: Vehicles | H27: Total
B28: WDV as at 1 April 2023 | C28: ='Fixed Assets P. Yr.'!B31 -> 0 | D28: =SUM('Fixed Assets P. Yr.'!B27:B28) -> 0 | E28: =SUM('Fixed Assets P. Yr.'!B9:B17) -> 0 | F28: ='Fixed Assets P. Yr.'!B24 -> 0 | G28: =SUM('Fixed Assets P. Yr.'!B20:B21) -> 0 | H28: =SUM(C28:G28) -> 0
B29: Additions | C29: ='Fixed Assets P. Yr.'!C31+'Fixed Assets P. Yr.'!D31 -> 0 | D29: ='Fixed Assets P. Yr.'!C27+'Fixed Assets P. Yr.'!C28+'Fixed Assets P. Yr.'!D27+'Fixed Assets P. Yr.'!D28 -> 0 | E29: =SUM('Fixed Assets P. Yr.'!C9:D17) -> 0 | F29: 0 | G29: =SUM('Fixed Assets P. Yr.'!C20:D21) -> 0 | H29: =SUM(C29:G29) -> 0
B30: Deductions/Adjustments | C30: ='Fixed Assets P. Yr.'!E31 -> 0 | D30: 0 | E30: =SUM('Fixed Assets P. Yr.'!E10:E10) -> 0 | F30: 0 | G30: =SUM('Fixed Assets P. Yr.'!E20:E21) -> 0 | H30: =SUM(C30:G30) -> 0
B31: Total | C31: =C28+C29-C30 -> 0 | D31: =D28+D29-D30 -> 0 | E31: =E28+E29-E30 -> 0 | F31: =F28+F29-F30 -> 0 | G31: =G28+G29-G30 -> 0 | H31: =H28+H29-H30 -> 0
B33: Depreciation/Adjustments
B34: At 1 April 2023 | C34: 0 | D34: 0 | E34: 0 | F34: 0 | G34: 0 | H34: =SUM(C34:G34) -> 0
B35: Additions | C35: ='Fixed Assets P. Yr.'!H31 -> 0 | D35: ='Fixed Assets P. Yr.'!H27+'Fixed Assets P. Yr.'!H28 -> 0 | E35: =SUM('Fixed Assets P. Yr.'!H9:H17) -> 0 | F35: ='Fixed Assets P. Yr.'!H24 -> 0 | G35: =SUM('Fixed Assets P. Yr.'!H20:H21) -> 0 | H35: =SUM(C35:G35) -> 0
B36: Deductions/Adjustments | C36: 0 | D36: 0 | E36: 0 | F36: 0 | G36: 0 | H36: =SUM(C36:G36) -> 0
B37: Total | C37: =C34+C35-C36 -> 0 | D37: =D34+D35-D36 -> 0 | E37: =E34+E35-E36 -> 0 | F37: =F34+F35-F36 -> 0 | G37: =G34+G35-G36 -> 0 | H37: =H34+H35-H36 -> 0
B39: WDV as at 31March 2024 | C39: =C31-C37 -> 0 | D39: =D31-D37 -> 0 | E39: =E31-E37 -> 0 | F39: =F31-F37 -> 0 | G39: =G31-G37 -> 0 | H39: =H31-H37 -> 0
B42: PREVIOUS YEAR (PY)
B43: Particulars /Assets | C43: Tangibles
C44: Land | D44: Furniture & Fixtures | E44: Plant And Machinery | F44: Computers | G44: Vehicles | H44: Total
B45: WDV as at 1 April 2021 | C45: ='FA2022'!C11 -> 0 | D45: =SUM('FA2022'!C13:C14) -> 17746.52 | E45: =SUM('FA2022'!C16:C24) -> 480494.89 | F45: ='FA2022'!C26 -> 7870.32 | G45: ='FA2022'!C28 -> 454987.87 | H45: =SUM(C45:G45) -> 961099.6
B46: Additions | C46: =SUM('FA2022'!D11:E11) -> 2168060 | D46: =SUM('FA2022'!D13:E14) -> 0 | E46: =SUM('FA2022'!D16:E24) -> 62486.75 | F46: =SUM('FA2022'!D26:E26) -> 0 | G46: =SUM('FA2022'!D28:E28) -> 0 | H46: =SUM(C46:G46) -> 2230546.8
B47: Deductions/Adjustments | C47: ='FA2022'!F11 -> 0 | D47: =SUM('FA2022'!F13:F14) -> 0 | E47: =SUM('FA2022'!F16:F24) -> 0 | F47: ='FA2022'!F26 -> 0 | G47: ='FA2022'!F28 -> 0 | H47: =SUM(C47:G47) -> 0
B48: Toal | C48: =+C45+C46-C47 -> 2168060 | D48: =+D45+D46-D47 -> 17746.52 | E48: =+E45+E46-E47 -> 542981.64 | F48: =+F45+F46-F47 -> 7870.32 | G48: =G45+G46-G47 -> 454987.87 | H48: =+H45+H46-H47 -> 3191646.4
B50: Depreciation/Adjustments
B51: At 1 April 2020 | C51: 0 | D51: 0 | E51: 0 | F51: 0 | G51: 0 | H51: =SUM(C51:G51) -> 0
B52: Additions | C52: ='FA2022'!I11 -> 0 | D52: =SUM('FA2022'!I13:I14) -> 2222.6745 | E52: =SUM('FA2022'!I16:I24) -> 80334.959 | F52: ='FA2022'!I26 -> 3148.128 | G52: ='FA2022'!I28 -> 68248.181 | H52: =SUM(C52:G52) -> 153953.94
B53: Deductions/Adjustments | C53: 0 | D53: 0 | E53: 0 | F53: 0 | G53: 0 | H53: =SUM(C53:G53) -> 0
...

Sheet Fixed Assets C. Yr.
A1: =bs!A1 -> M/S XYZ CO.
A2: Notes forming part of the Financial Statements for the year ended, 31st March, 2025
A3: 7. Property,plant and equipments
A4: DETAIL OF FIXED ASSETS
A5: PARTICULARS | B5: W.D.V | C5: ADDITIONS | D5: ADDITIONS | G5: RATE | I5: W.D.V
B6: AS ON | C6: GREATER THAN | D6: LESS THAN | E6: SALE | F6: TOTAL | H6: DEPRECIATION | I6: AS ON | K6: 6141
B7: 01.04.2024 | C7: 180 DAYS | D7: 180 DAYS | I7: 31.03.2025
B8: Amount in Rs. | C8: =B8 -> Amount in Rs. | D8: =C8 -> Amount in Rs. | E8: =D8 -> Amount in Rs. | F8: =E8 -> Amount in Rs. | G8: % | H8: =F8 -> Amount in Rs. | I8: =H8 -> Amount in Rs.
A10: PLANT & MACHINERY
C11: 0 | D11: 0 | E11: 0 | F11: =B11+C11+D11-E11 -> 0 | G11: 15 | H11: =(B11+C11-E11)*G11/100+(D11*G11/200) -> 0 | I11: =F11-H11 -> 0
C12: 0 | D12: 0 | E12: 0 | F12: =B12+C12+D12-E12 -> 0 | G12: 15 | H12: =(B12+C12-E12)*G12/100+(D12*G12/200) -> 0 | I12: =F12-H12 -> 0
C13: 0 | D13: 0 | E13: 0 | F13: =B13+C13+D13-E13 -> 0 | G13: 15 | H13: =(B13+C13-E13)*G13/100+(D13*G13/200) -> 0 | I13: =F13-H13 -> 0 | K13: 17945.2
C14: 0 | D14: 0 | E14: 0 | F14: =B14+C14+D14-E14 -> 0 | G14: 15 | H14: =(B14+C14-E14)*G14/100+(D14*G14/200) -> 0 | I14: =F14-H14 -> 0
C15: 0 | D15: 0 | E15: 0 | F15: =B15+C15+D15-E15 -> 0 | G15: 15 | H15: =(B15+C15-E15)*G15/100+(D15*G15/200) -> 0 | I15: =F15-H15 -> 0
C16: 0 | D16: 0 | E16: 0 | F16: =B16+C16+D16-E16 -> 0 | G16: 15 | H16: =(B16+C16-E16)*G16/100+(D16*G16/200) -> 0 | I16: =F16-H16 -> 0
C17: 0 | D17: 0 | E17: 0 | F17: =B17+C17+D17-E17 -> 0 | G17: 15 | H17: =(B17+C17-E17)*G17/100+(D17*G17/200) -> 0 | I17: =F17-H17 -> 0
C18: 0 | D18: 0 | E18: 0 | F18: =B18+C18+D18-E18 -> 0 | G18: 15 | H18: =(B18+C18-E18)*G18/100+(D18*G18/200) -> 0 | I18: =F18-H18 -> 0
C19: 0 | D19: 0 | E19: 0 | F19: =B19+C19+D19-E19 -> 0 | G19: 15 | H19: =(B19+C19-E19)*G19/100+(D19*G19/200) -> 0 | I19: =F19-H19 -> 0
C20: 0 | D20: 0 | E20: 0 | F20: =B20+C20+D20-E20 -> 0 | G20: 15 | H20: =(B20+C20-E20)*G20/100+(D20*G20/200) -> 0 | I20: =F20-H20 -> 0
C21: 0 | D21: 0 | E21: 0 | F21: =B21+C21+D21-E21 -> 0 | G21: 15 | H21: =(B21+C21-E21)*G21/100+(D21*G21/200) -> 0 | I21: =F21-H21 -> 0
A23: VEHICLE
A24: Car | C24: 0 | D24: 0 | E24: 0 | F24: =B24+C24+D24-E24 -> 0 | G24: 15 | H24: =(B24+C24-E24)*G24/100+(D24*G24/200) -> 0 | I24: =F24-H24 -> 0
A25: Motor Cycle & Scooter | C25: 0 | D25: 0 | E25: 0 | F25: =B25+C25+D25-E25 -> 0 | G25: 15 | H25: =(B25+C25-E25)*G25/100+(D25*G25/200) -> 0 | I25: =F25-H25 -> 0 | K25: 3166.728
C26: 0 | D26: 0 | E26: 0 | F26: =B26+C26+D26-E26 -> 0 | G26: 15 | H26: =(B26+C26-E26)*G26/100+(D26*G26/200) -> 0 | I26: =F26-H26 -> 0
C27: 0 | D27: 0 | E27: 0 | F27: =B27+C27+D27-E27 -> 0 | G27: 15 | H27: =(B27+C27-E27)*G27/100+(D27*G27/200) -> 0 | I27: =F27-H27 -> 0
C28: 0 | D28: 0 | E28: 0 | F28: =B28+C28+D28-E28 -> 0 | G28: 15 | H28: =(B28+C28-E28)*G28/100+(D28*G28/200) -> 0 | I28: =F28-H28 -> 0
C29: 0 | D29: 0 | E29: 0 | F29: =B29+C29+D29-E29 -> 0 | G29: 15 | H29: =(B29+C29-E29)*G29/100+(D29*G29/200) -> 0 | I29: =F29-H29 -> 0
C30: 0 | D30: 0 | E30: 0 | F30: =B30+C30+D30-E30 -> 0 | G30: 15 | H30: =(B30+C30-E30)*G30/100+(D30*G30/200) -> 0 | I30: =F30-H30 -> 0
C31: 0 | D31: 0 | E31: 0 | F31: =B31+C31+D31-E31 -> 0 | G31: 15 | H31: =(B31+C31-E31)*G31/100+(D31*G31/200) -> 0 | I31: =F31-H31 -> 0
C32: 0 | D32: 0 | E32: 0 | F32: =B32+C32+D32-E32 -> 0 | G32: 15 | H32: =(B32+C32-E32)*G32/100+(D32*G32/200) -> 0 | I32: =F32-H32 -> 0
C33: 0 | D33: 0 | E33: 0 | F33: =B33+C33+D33-E33 -> 0 | G33: 15 | H33: =(B33+C33-E33)*G33/100+(D33*G33/200) -> 0 | I33: =F33-H33 -> 0
A35: FURNITURE AND FIXTURES
A36: Furniture & Fixture | C36: 0 | D36: 0 | E36: 0 | F36: =B36+C36+D36-E36 -> 0 | G36: 10 | H36: =(B36+C36-E36)*G36/100+(D36*G36/200) -> 0 | I36: =F36-H36 -> 0
C37: 0 | D37: 0 | E37: 0 | F37: =B37+C37+D37-E37 -> 0 | G37: 10 | H37: =(B37+C37-E37)*G37/100+(D37*G37/200) -> 0 | I37: =F37-H37 -> 0
C38: 0 | D38: 0 | E38: 0 | F38: =B38+C38+D38-E38 -> 0 | G38: 10 | H38: =(B38+C38-E38)*G38/100+(D38*G38/200) -> 0 | I38: =F38-H38 -> 0
C39: 0 | D39: 0 | E39: 0 | F39: =B39+C39+D39-E39 -> 0 | G39: 10 | H39: =(B39+C39-E39)*G39/100+(D39*G39/200) -> 0 | I39: =F39-H39 -> 0
C40: 0 | D40: 0 | E40: 0 | F40: =B40+C40+D40-E40 -> 0 | G40: 10 | H40: =(B40+C40-E40)*G40/100+(D40*G40/200) -> 0 | I40: =F40-H40 -> 0
C41: 0 | D41: 0 | E41: 0 | F41: =B41+C41+D41-E41 -> 0 | G41: 10 | H41: =(B41+C41-E41)*G41/100+(D41*G41/200) -> 0 | I41: =F41-H41 -> 0
C42: 0 | D42: 0 | E42: 0 | F42: =B42+C42+D42-E42 -> 0 | G42: 10 | H42: =(B42+C42-E42)*G42/100+(D42*G42/200) -> 0 | I42: =F42-H42 -> 0
C43: 0 | D43: 0 | E43: 0 | F43: =B43+C43+D43-E43 -> 0 | G43: 10 | H43: =(B43+C43-E43)*G43/100+(D43*G43/200) -> 0 | I43: =F43-H43 -> 0
...

Sheet Fixed Assets P. Yr.
A1: =bs!A1 -> M/S XYZ CO.
A2: DETAIL OF FIXED ASSETS
A3: PARTICULARS | B3: W.D.V | C3: ADDITIONS | D3: ADDITIONS | G3: RATE | I3: W.D.V
B4: AS ON | C4: GREATER THAN | D4: LESS THAN | E4: SALE | F4: TOTAL | H4: DEPRECIATION | I4: AS ON
B5: 01.04.2023 | C5: 180 DAYS | D5: 180 DAYS | I5: 31.03.2024
B6: Amount in Rs. | C6: =B6 -> Amount in Rs. | D6: =C6 -> Amount in Rs. | E6: =D6 -> Amount in Rs. | F6: =E6 -> Amount in Rs. | G6: % | H6: =F6 -> Amount in Rs. | I6: =H6 -> Amount in Rs.
A8: PLANT & MACHINERY | H8: =(B8+C8)*G8/100+(D8*G8/200) -> 0
A9: Camera & DVR | B9: 0 | C9: 0 | D9: 0 | F9: =B9+C9+D9-E9 -> 0 | G9: 15 | H9: =ROUND(((B9+C9)*G9%+D9*G9%/2),0) -> 0 | I9: =F9-H9 -> 0
A10: Digital Moisture Meter | B10: 0 | C10: 0 | D10: 0 | F10: 0 | G10: 15 | H10: =ROUND(((B10+C10)*G10%+D10*G10%/2),0) -> 0 | I10: =F10-H10 -> 0
A11: Servo Control Voltage Stablizer 3 | B11: 0 | C11: 0 | D11: 0 | F11: =B11+C11+D11-E11 -> 0 | G11: 15 | H11: =ROUND(((B11+C11)*G11%+D11*G11%/2),0) -> 0 | I11: =F11-H11 -> 0
A12: Water Cooler | B12: 0 | C12: 0 | D12: 0 | F12: =B12+C12+D12-E12 -> 0 | G12: 15 | H12: =ROUND(((B12+C12)*G12%+D12*G12%/2),0) -> 0 | I12: =F12-H12 -> 0
A13: Machine | B13: 0 | C13: 0 | D13: 0 | F13: =B13+C13+D13-E13 -> 0 | G13: 15 | H13: =ROUND(((B13+C13)*G13%+D13*G13%/2),0) -> 0 | I13: =F13-H13 -> 0
A14: Mobile | B14: 0 | C14: 0 | D14: 0 | F14: =B14+C14+D14-E14 -> 0 | G14: 15 | H14: =ROUND(((B14+C14)*G14%+D14*G14%/2),0) -> 0 | I14: =F14-H14 -> 0
A15: Electricals | B15: 0 | C15: 0 | D15: 0 | F15: =B15+C15+D15-E15 -> 0 | G15: 15 | H15: =ROUND(((B15+C15)*G15%+D15*G15%/2),0) -> 0 | I15: =F15-H15 -> 0
A16: Washing Machine | B16: 0 | C16: 0 | D16: 0 | F16: =B16+C16+D16-E16 -> 0 | G16: 15 | H16: =ROUND(((B16+C16)*G16%+D16*G16%/2),0) -> 0 | I16: =F16-H16 -> 0
A17: LED | B17: 0 | C17: 0 | D17: 0 | F17: =B17+C17+D17-E17 -> 0 | G17: 15 | H17: =ROUND(((B17+C17)*G17%+D17*G17%/2),0) -> 0 | I17: =F17-H17 -> 0
A19: VEHICLE | H19: =(B19+C19)*G19/100+(D19*G19/200) -> 0
A20: Car | B20: 0 | C20: 0 | D20: 0 | E20: 0 | F20: =B20+C20+D20-E20 -> 0 | G20: 15 | H20: =ROUND(((B20+C20-E20)*G20%+D20*G20%/2),0) -> 0 | I20: =F20-H20 -> 0
A21: Motor Cycle & Scooter | B21: 0 | C21: 0 | D21: 0 | F21: =B21+C21+D21-E21 -> 0 | G21: 15 | H21: =ROUND(((B21+C21-E21)*G21%+D21*G21%/2),0) -> 0 | I21: =F21-H21 -> 0
A23: COMPUTERS
A24: Computer | B24: 0 | C24: 0 | D24: 0 | F24: =B24+C24+D24-E24 -> 0 | G24: 40 | H24: =ROUND(((B24+C24)*G24%+D24*G24%/2),0) -> 0 | I24: =F24-H24 -> 0
A26: FURNITURE AND FIXTURES
A27: Chair | B27: 0 | C27: 0 | D27: 0 | F27: =B27+C27+D27-E27 -> 0 | G27: 10 | H27: =ROUND(((B27+C27)*G27%+D27*G27%/2),0) -> 0 | I27: =F27-H27 -> 0
A28: Furniture & Fixture | B28: 0 | C28: 0 | D28: 0 | F28: =B28+C28+D28-E28 -> 0 | G28: 10 | H28: =ROUND(((B28+C28)*G28%+D28*G28%/2),0) -> 0 | I28: =F28-H28 -> 0
A30: BUILDING
A31: Building | B31: 0 | C31: 0 | D31: 0 | F31: =B31+C31+D31-E31 -> 0 | G31: 10 | H31: =ROUND(((B31+C31)*G31%+D31*G31%/2),0) -> 0 | I31: =F31-H31 -> 0
H36: =(B36+C36)*G36/100+(D36*G36/200) -> 0
A37: Total | B37: =SUM(B7:B36) -> 0 | C37: =SUM(C7:C36) -> 0 | D37: =SUM(D7:D36) -> 0 | E37: =SUM(E7:E36) -> 0 | F37: =SUM(F7:F36) -> 0 | H37: =SUM(H7:H36) -> 0 | I37: =SUM(I7:I36) -> 0 | J37: =H37-'p&l'!F13 -> 0
I39: =I37-bs!F26 -> 0

Sheet Details
A1: =bs!A1 -> M/S XYZ CO.
A2: Supplementary Details forming part of the Financial Statements for the year ended, 31st March, 2025
A4: UNSECURED LOAN
A5: PARTICULARS | D5: ='notes to bs'!D4 -> As at 31.03.2025 | E5: ='notes to bs'!E4 -> As at 31.03.2024
B6: FROM RELATED PARTIES
B13: Total | D13: =SUM(D7:D12) -> 0 | E13: =SUM(E7:E12) -> 0
B15: FROM OTHER PARTIES | D15: 0 | E15: 0
B17: Total | D17: =SUM(D15:D15) -> 0 | E17: =SUM(E15:E15) -> 0
A19: TOTAL | D19: =D13+D17 -> 0 | E19: =E13+E17 -> 0
A21: SUNDRY CREDITORS
A22: PARTICULARS | D22: =D5 -> As at 31.03.2025 | E22: =E5 -> As at 31.03.2024
A23: M/s.
A24: M/s.
A25: M/s.
A26: M/s.
A27: M/s.
A28: M/s.
A29: M/s.
A30: M/s.
A31: M/s.
A32: M/s.
A33: M/s.
A34: M/s.
... A55: M/s.
B56: Advance from Customers
A57: M/s.
A58: M/s.
A59: M/s.
A60: M/s.
A61: M/s.
D62: =SUM(D23:D61) -> 0 | E62: =SUM(E23:E61) -> 0
A63: DUE TO MSME CREDITORS
D68: =SUM(D64:D64) -> 0 | E68: =SUM(E64:E64) -> 0
A69: TOTAL | D69: =D62+D68 -> 0 | E69: =E62+E68 -> 0
A72: TRADE RECEIVABLE (Outstanding for a period less than 6 months from the date they are due for receipt)
A73: PARTICULARS | D73: =D22 -> As at 31.03.2025 | E73: =E22 -> As at 31.03.2024
A74: M/s.
A75: M/s.
A76: M/s.
A77: M/s.
...

Sheet GROSS PROFIT
A1: =bs!A1 -> M/S XYZ CO.
A2: =bs!A1 -> M/S XYZ CO.
A4: TRADING ACCOUNT FOR THE YEAR ENDING 31ST MARCH ,2025
A6: PARTICULARS | B6: CURRENT YEAR | C6: PREVIOUS YEAR | D6: PARTICULARS | E6: CURRENT YEAR | F6: PREVIOUS YEAR
B7: 31.03.2025 | C7: 31.03.2024 | E7: 31.03.2025 | F7: 31.03.2024
B8: Rs. P | C8: Rs. P | E8: Rs. P | F8: Rs. P
A9: OPENING STOCK | B9: ='notes to p&l'!D18 -> 0 | C9: ='notes to p&l'!E18 -> 0 | D9: SALES
D10: Sales GST | E10: ='notes to p&l'!D6 -> 0 | F10: ='notes to p&l'!E6 -> 0
A12: PURCHASES
A13: Purchase GST | B13: ='notes to p&l'!D21 -> 0 | C13: ='notes to p&l'!E21 -> 0 | D13: CLOSING STOCK | F13: ='notes to p&l'!E27 -> 0
D14: (As Certified by the Proprietor)
A16: DIRECT EXPENSES
A21: F.O.C. | B21: ='notes to p&l'!D24 -> 0
A22: Freight Inward | C22: 0
A23: Frieght Inward (GST) | C23: 0
A25: GROSS PROFIT | B25: =E27-SUM(B9:B23) -> 0 | C25: =F27-SUM(C9:C21) -> 0
A27: TOTAL | B27: =SUM(B9:B26) -> 0 | C27: =SUM(C9:C26) -> 0 | D27: TOTAL | E27: =SUM(E9:E26) -> 0 | F27: =SUM(F9:F26) -> 0

Sheet FA2022
B3: SHRAMANSRI INTERNATIONAL
B4: DETAIL OF FIXED ASSETS
B5: PARTICULARS | C5: W.D.V | D5: ADDITIONS | E5: ADDITIONS | H5: RATE | J5: W.D.V
C6: AS ON | D6: GREATER THAN | E6: LESS THAN | F6: SALE | G6: TOTAL | I6: DEPRECIATION | J6: AS ON
C7: 01.04.2021 | D7: 180 DAYS | E7: 180 DAYS | J7: 31.03.2022
C8: =[1]ANNEX.!G155 -> Amount in Rs. | D8: =C8 -> Amount in Rs. | E8: =D8 -> Amount in Rs. | F8: =E8 -> Amount in Rs. | G8: =F8 -> Amount in Rs. | H8: % | I8: =G8 -> Amount in Rs. | J8: =I8 -> Amount in Rs.
B10: LAND
B11: LAND | D11: 2168060 | G11: =C11+D11+E11-F11 -> 2168060 | I11: =(C11+D11)*H11/100+(E11*H11)/200 -> 0 | J11: =G11-I11 -> 2168060
B12: FURNITURE & FIXTURE
B13: FURNITURE AND FIXTURE | C13: 8786.07 | G13: =C13+D13+E13-F13 -> 8786.07 | H13: 10 | I13: =(C13+D13)*H13/100+(E13*H13)/200 -> 878.607 | J13: =G13-I13 -> 7907.463
B14: FAN | C14: 8960.45 | G14: =C14+D14+E14-F14 -> 8960.45 | H14: 15 | I14: =(C14+D14)*H14/100+(E14*H14)/200 -> 1344.0675 | J14: =G14-I14 -> 7616.3825
B15: PLANT & MACHINERY
B16: AIR CONDITIONER | C16: 14297.55 | G16: =C16+D16+E16-F16 -> 14297.55 | H16: 15 | I16: =(C16+D16)*H16/100+(E16*H16)/200 -> 2144.6325 | J16: =G16-I16 -> 12152.917
B17: CAMERA | C17: 20205.44 | D17: 47656.25 | G17: =C17+D17+E17-F17 -> 67861.69 | H17: 15 | I17: =(C17+D17)*H17/100+(E17*H17)/200 -> 10179.254 | J17: =G17-I17 -> 57682.437
B18: ELECTRICAL FITTINGS | C18: 16617.5 | G18: =C18+D18+E18-F18 -> 16617.5 | H18: 15 | I18: =(C18+D18)*H18/100+(E18*H18)/200 -> 2492.625 | J18: =G18-I18 -> 14124.875
B19: GENERATOR | C19: 13510.75 | G19: =C19+D19+E19-F19 -> 13510.75 | H19: 15 | I19: =(C19+D19)*H19/100+(E19*H19)/200 -> 2026.6125 | J19: =G19-I19 -> 11484.138
B20: MACHINERY | C20: 404338.53 | G20: =C20+D20+E20-F20 -> 404338.53 | H20: 15 | I20: =(C20+D20)*H20/100+(E20*H20)/200 -> 60650.78 | J20: =G20-I20 -> 343687.75
B21: MOBILE | E21: 14830.5 | G21: =C21+D21+E21-F21 -> 14830.5 | H21: 15 | I21: =(C21+D21)*H21/100+(E21*H21)/200 -> 1112.2875 | J21: =G21-I21 -> 13718.212
B22: ROOM HEATER | C22: 5663.66 | G22: =C22+D22+E22-F22 -> 5663.66 | H22: 15 | I22: =(C22+D22)*H22/100+(E22*H22)/200 -> 849.549 | J22: =G22-I22 -> 4814.111
B23: WATER COOLER | C23: 4071.29 | G23: =C23+D23+E23-F23 -> 4071.29 | H23: 15 | I23: =(C23+D23)*H23/100+(E23*H23)/200 -> 610.6935 | J23: =G23-I23 -> 3460.5965
B24: WEIGHT SCALE | C24: 1790.17 | G24: =C24+D24+E24-F24 -> 1790.17 | H24: 15 | I24: =(C24+D24)*H24/100+(E24*H24)/200 -> 268.5255 | J24: =G24-I24 -> 1521.6445
B25: COMPUTER
B26: COMPUTER | C26: 7870.32 | G26: =C26+D26+E26-F26 -> 7870.32 | H26: 40 | I26: =(C26+D26)*H26/100+(E26*H26)/200 -> 3148.128 | J26: =G26-I26 -> 4722.192
B27: VEHICLE
B28: CAR | C28: 454987.87 | G28: =C28+D28+E28-F28 -> 454987.87 | H28: 15 | I28: =(C28+D28)*H28/100+(E28*H28)/200 -> 68248.181 | J28: =G28-I28 -> 386739.69
I29: =(C29+D29)*H29/100+(E29*H29)/200 -> 0
B30: Total | C30: 882929.71 | D30: =SUM(D10:D29) -> 2215716.2 | E30: =SUM(E10:E29) -> 14830.5 | F30: =SUM(F10:F29) -> 0 | G30: =SUM(G10:G29) -> 3191646.4 | H30: =SUM(H10:H29) -> 215 | I30: =SUM(I10:I29) -> 153953.94 | J30: =SUM(J10:J29) -> 3037692.4
